<?xml version="1.0"?>
<robot name="hitc_robot_description">
  <link name="base_link">
    <inertial>
      <origin
        xyz="0.401377631632735 -5.42648148638136E-10 -0.0374917413193443"
        rpy="0 0 0" />
      <mass
        value="4.99823696772836" />
      <inertia
        ixx="0.0169614503869467"
        ixy="1.82208114342673E-12"
        ixz="0.00916365672383926"
        iyy="0.0927621254573851"
        iyz="-5.3801530305262E-13"
        izz="0.0980634664778844" />
    </inertial>
    <visual>
      <origin
        xyz="0 0 0"
        rpy="0 0 0" />
      <geometry>
        <mesh
          filename="package://hitc_robot_description/meshes/base_link.STL" />
      </geometry>
      <material
        name="">
        <color
          rgba="0.792156862745098 0.819607843137255 0.933333333333333 1" />
      </material>
    </visual>
    <collision>
      <origin
        xyz="0 0 0"
        rpy="0 0 0" />
      <geometry>
        <mesh
          filename="package://hitc_robot_description/meshes/base_link.STL" />
      </geometry>
    </collision>
  </link>
  <link
    name="link1">
    <inertial>
      <origin
        xyz="0.127456995432329 -3.91852883474542E-10 -0.000990640138830434"
        rpy="0 0 0" />
      <mass
        value="1.72026759907067" />
      <inertia
        ixx="0.00177938153925269"
        ixy="-2.28571691090452E-11"
        ixz="-2.49254882124087E-05"
        iyy="0.00317233587831757"
        iyz="-2.13357891927353E-12"
        izz="0.00368233931714265" />
    </inertial>
    <visual>
      <origin
        xyz="0 0 0"
        rpy="0 0 0" />
      <geometry>
        <mesh
          filename="package://hitc_robot_description/meshes/link1.STL" />
      </geometry>
      <material
        name="">
        <color
          rgba="0.792156862745098 0.819607843137255 0.933333333333333 1" />
      </material>
    </visual>
    <collision>
      <origin
        xyz="0 0 0"
        rpy="0 0 0" />
      <geometry>
        <mesh
          filename="package://hitc_robot_description/meshes/link1.STL" />
      </geometry>
    </collision>
  </link>
  <joint
    name="base_L1"
    type="continuous">
    <origin
      xyz="0.12 0 0"
      rpy="0 0 1.02821445685467" />
    <parent
      link="base_link" />
    <child
      link="link1" />
    <axis
      xyz="0 0 1" />
  </joint>
  <link
    name="link2">
    <inertial>
      <origin
        xyz="0.158530571849047 2.61089622144439E-10 -0.000944098303645058"
        rpy="0 0 0" />
      <mass
        value="1.80507291432319" />
      <inertia
        ixx="0.00178995620687186"
        ixy="-4.12342378852315E-11"
        ixz="-2.49254881484251E-05"
        iyy="0.00368804550872146"
        iyz="-9.95293306947325E-13"
        izz="0.00415400293912304" />
    </inertial>
    <visual>
      <origin
        xyz="0 0 0"
        rpy="0 0 0" />
      <geometry>
        <mesh
          filename="package://hitc_robot_description/meshes/link2.STL" />
      </geometry>
      <material
        name="">
        <color
          rgba="0.792156862745098 0.819607843137255 0.933333333333333 1" />
      </material>
    </visual>
    <collision>
      <origin
        xyz="0 0 0"
        rpy="0 0 0" />
      <geometry>
        <mesh
          filename="package://hitc_robot_description/meshes/link2.STL" />
      </geometry>
    </collision>
  </link>
  <joint
    name="L1-L2"
    type="continuous">
    <origin
      xyz="0.349999999999999 0 0"
      rpy="0 0 -1.5707963267949" />
    <parent
      link="link1" />
    <child
      link="link2" />
    <axis
      xyz="0 0 1" />
  </joint>
</robot>