<?xml version="1.0" encoding="utf-8"?>
<!-- This URDF was automatically created by SolidWorks to URDF Exporter! Originally created by Stephen Brawner (brawner@gmail.com) 
     Commit Version: 1.6.0-4-g7f85cfe  Build Version: 1.6.7995.38578
     For more information, please see http://wiki.ros.org/sw_urdf_exporter -->
<robot
  name="HITC_platform">
  <link
    name="base_link">
    <inertial>
      <origin
        xyz="0.40138 -5.4265E-10 -0.037492"
        rpy="0 0 0" />
      <mass
        value="4.9982" />
      <inertia
        ixx="0.016961"
        ixy="1.8221E-12"
        ixz="0.0091637"
        iyy="0.092762"
        iyz="-5.3802E-13"
        izz="0.098063" />
    </inertial>
    <visual>
      <origin
        xyz="0 0 0"
        rpy="0 0 0" />
      <geometry>
        <mesh
          filename="package://HITC_platform/meshes/base_link.STL" />
      </geometry>
      <material
        name="">
        <color
          rgba="0.79216 0.81961 0.93333 1" />
      </material>
    </visual>
    <collision>
      <origin
        xyz="0 0 0"
        rpy="0 0 0" />
      <geometry>
        <mesh
          filename="package://HITC_platform/meshes/base_link.STL" />
      </geometry>
    </collision>
  </link>
  <link
    name="link1">
    <inertial>
      <origin
        xyz="0.12746 -1.4111E-09 -0.00099064"
        rpy="0 0 0" />
      <mass
        value="1.7203" />
      <inertia
        ixx="0.0017794"
        ixy="-2.0011E-11"
        ixz="-2.4925E-05"
        iyy="0.0031723"
        iyz="-1.4652E-12"
        izz="0.0036823" />
    </inertial>
    <visual>
      <origin
        xyz="0 0 0"
        rpy="0 0 0" />
      <geometry>
        <mesh
          filename="package://HITC_platform/meshes/link1.STL" />
      </geometry>
      <material
        name="">
        <color
          rgba="0.79216 0.81961 0.93333 1" />
      </material>
    </visual>
    <collision>
      <origin
        xyz="0 0 0"
        rpy="0 0 0" />
      <geometry>
        <mesh
          filename="package://HITC_platform/meshes/link1.STL" />
      </geometry>
    </collision>
  </link>
  <joint
    name="base_L1"
    type="continuous">
    <origin
      xyz="0.12 0 0"
      rpy="0 0 1.491" />
    <parent
      link="base_link" />
    <child
      link="link1" />
    <axis
      xyz="0 0 1" />
  </joint>
  <link
    name="link2">
    <inertial>
      <origin
        xyz="0.15853 2.6055E-10 -0.0009441"
        rpy="0 0 0" />
      <mass
        value="1.8051" />
      <inertia
        ixx="0.00179"
        ixy="-4.0801E-11"
        ixz="-2.4925E-05"
        iyy="0.003688"
        iyz="-8.8192E-13"
        izz="0.004154" />
    </inertial>
    <visual>
      <origin
        xyz="0 0 0"
        rpy="0 0 0" />
      <geometry>
        <mesh
          filename="package://HITC_platform/meshes/link2.STL" />
      </geometry>
      <material
        name="">
        <color
          rgba="0.79216 0.81961 0.93333 1" />
      </material>
    </visual>
    <collision>
      <origin
        xyz="0 0 0"
        rpy="0 0 0" />
      <geometry>
        <mesh
          filename="package://HITC_platform/meshes/link2.STL" />
      </geometry>
    </collision>
  </link>
  <joint
    name="L1-L2"
    type="continuous">
    <origin
      xyz="0.35 0 0"
      rpy="0 0 -1.7602" />
    <parent
      link="link1" />
    <child
      link="link2" />
    <axis
      xyz="0 0 1" />
  </joint>
</robot>